File: DataManager/Data Set
File Path: C:\Users\MEUser\Desktop\Fu\Test Run 1 10-21-21 17 37 15 PM\DAQ- Crosshead, … - (Timed).txt
Test: MTS EM Tension (Extensometer) 81
Test Run: Test Run 1
Date: 10/21/2021 4:56:50 PM


Crosshead 	Load 	Time 	Extensometer
in	lbf	sec	in
0.00338358497503764	213.912336722626	0.112999998033047	-3.89189343569721E-05
0.00676482560215738	349.316269744719	0.212999999523163	-4.57459856172465E-05
0.0101413763876212	468.100024365003	0.312999993562698	-4.17270261038546E-05
0.0135015133001996	562.010941670134	0.412999987602234	-3.93555141931219E-05
0.0168522705294661	644.843048133129	0.513000011444092	-4.71709337557334E-05
0.0201983379170768	728.384049202831	0.612999975681305	-5.74476823067374E-05
0.0235373722609338	814.200637086463	0.712999999523163	-5.22836680686414E-05
0.0268717156173148	902.611144760094	0.813000023365021	-4.70387571413729E-05
0.0302060589736958	992.491637278217	0.912999987602234	-5.623424092087E-05
0.0335404023300768	1082.86066114461	1.01300001144409	-6.81816130763334E-05
0.0368700569906221	1172.24899990474	1.11300003528595	-5.60130752629039E-05
0.0402044026386433	1258.31932112429	1.21300005912781	-7.43817306610304E-05
0.0435410903429422	1338.32375259986	1.31299996376038	-9.26015637223755E-05
0.0468777780472411	1410.1438432607	1.41299998760223	-9.33334473574371E-05
0.05021446575154	1472.80428673012	1.51300001144409	-9.49275964221598E-05
0.0535488113995612	1526.27939683006	1.61300003528595	-9.30427044596134E-05
0.0568901877996959	1571.7773020897	1.71300005912781	-0.000102786606382904
0.0602245334477171	1609.54685108033	1.81299996376038	-0.000108832114344159
0.063561221152016	1640.345566515	1.91299998760223	-0.000121520935046976
0.0668955622167569	1665.56335602922	2.01300001144409	-0.000118422691215757
0.0702322545043362	1686.03677673011	2.11299991607666	-0.000121640324130023
0.0727576328309502	1690.1724709392	2.21300005912781	-0.000113818553322422
0.0727552861913921	1662.43666758427	2.31299996376038	-0.000112070022903105
0.0727294914893747	1654.45693803416	2.41300010681152	-0.000114894630572475
0.07268963069985	1649.52343552504	2.51300001144409	-0.000106121972312108
0.072654458606161	1645.54196815435	2.61299991607666	-0.000109826918932821
0.0726263218478659	1642.20748511503	2.71300005912781	-0.000103167036558455
0.0726052158416843	1639.50319159833	2.81299996376038	-0.000103836831067025
0.0725911497541769	1637.31734175265	2.91300010681152	-0.000107002454490963
0.0725794257229473	1635.5329207668	3.01300001144409	-0.000106744081010872
0.0725723903875534	1634.02566901011	3.11299991607666	-0.000106789430421887
0.0725700437479953	1632.79174453287	3.21300005912781	-0.00010317581819529
0.0725653550521595	1631.75123478109	3.31299996376038	-0.000103917405494295
0.0725630084126014	1630.72488535825	3.41300010681152	-0.00010800838606697
0.0725630084126014	1629.89359721074	3.51300001144409	-0.000102065724411115
0.0725630084126014	1629.18975202365	3.61299991607666	-0.000107834686901683
0.0725630084126014	1628.41905691159	3.71300005912781	-0.000108928739204503
0.0725630084126014	1627.82575010619	3.81299996376038	-0.000108405323213289
0.0725630084126014	1627.27448520763	3.91300010681152	-0.000107840022126508
0.0725630084126014	1626.77514151517	4.01300001144409	-0.000103883424767052
0.0725630084126014	1626.2360610857	4.11299991607666	-0.000107165805468502
0.0725630084126014	1625.72991165375	4.21299982070923	-0.000111405697895153
0.0725630084126014	1625.28237939739	4.31300020217896	-0.000105938435207083
0.0725630084126014	1624.86821721853	4.41300010681152	-0.000101779985524495
0.0725630084126014	1624.44340735046	4.51300001144409	-0.000101639667321244
0.0725653550521595	1624.08094683771	4.61299991607666	-0.000109554518108264
0.0725653550521595	1623.74153802323	4.71299982070923	-0.000115388192579138
0.0725630084126014	1623.35701374213	4.81300020217896	-0.00010571142855214
0.0725653550521595	1622.96612280152	4.91300010681152	-0.000108610532431236
0.0725653550521595	1622.65360763501	5.01300001144409	-0.000110733191015572
0.0725653550521595	1622.40739354352	5.11299991607666	-0.000106034872081318
0.0725653550521595	1622.00936755345	5.21299982070923	-0.000109279270636905
0.0725653550521595	1621.7878517101	5.31300020217896	-0.000110697598978817
0.0725653550521595	1621.43494118663	5.41300010681152	-0.000104603071401549
0.0725653550521595	1621.16139436719	5.51300001144409	-0.000100524005567537
0.0725653550521595	1620.87072342904	5.61299991607666	-0.000109506644312348
0.0725653550521595	1620.62286278768	5.71299982070923	-0.000106277374162726
0.0725653550521595	1620.35326768795	5.81300020217896	-0.000104325935117374
0.0725653550521595	1620.15096159315	5.91300010681152	-0.000107852160658158
0.0725653550521595	1619.90815037141	6.01300001144409	-0.000112568741100203
0.0725653550521595	1619.64766618099	6.11299991607666	-0.00010729149656208
0.0725653550521595	1619.42615033764	6.21299982070923	-0.000100821739758294
0.0725677016917176	1619.21835574326	6.31300020217896	-0.000101862905302276
0.0725653550521595	1618.95501753306	6.41300010681152	-0.000109358368030457
0.0725653550521595	1618.80375448443	6.51300001144409	-0.000105034410005929
0.0725677016917176	1618.64074604669	6.61299991607666	-0.000106318954899829
0.0725653550521595	1618.36149118768	6.71299982070923	-0.000107447265433198
0.0725653550521595	1618.14952533361	6.81300020217896	-0.000109916087010817
0.0725677016917176	1618.00528756446	6.91300010681152	-0.000108219020026938
0.0725677016917176	1617.74096142433	7.01300001144409	-0.000111103040258667
0.0725653550521595	1617.59266216548	7.11299991607666	-0.000108383713762402
0.0725677016917176	1617.46258472526	7.21299982070923	-0.000111267689235534
0.0725653550521595	1617.20912581431	7.31300020217896	-0.000103458522448997
0.0725677016917176	1617.02548061812	7.41300010681152	-0.000104847274309663
0.0725677016917176	1616.80736764451	7.51300001144409	-0.000105423022053107